{"trial_id": "06", "hyperparameters": {"space": [{"class_name": "Int", "config": {"name": "filters", "default": null, "conditions": [], "min_value": 32, "max_value": 128, "step": 32, "sampling": "linear"}}, {"class_name": "Choice", "config": {"name": "kernel_size", "default": 3, "conditions": [], "values": [3, 5], "ordered": true}}, {"class_name": "Float", "config": {"name": "dropout", "default": 0.3, "conditions": [], "min_value": 0.3, "max_value": 0.5, "step": 0.1, "sampling": "linear"}}, {"class_name": "Float", "config": {"name": "dropout_fc", "default": 0.3, "conditions": [], "min_value": 0.3, "max_value": 0.5, "step": 0.1, "sampling": "linear"}}, {"class_name": "Choice", "config": {"name": "learning_rate", "default": 0.01, "conditions": [], "values": [0.01, 0.001], "ordered": true}}, {"class_name": "Float", "config": {"name": "dropout_rate", "default": 0.3, "conditions": [], "min_value": 0.3, "max_value": 0.5, "step": 0.1, "sampling": "linear"}}], "values": {"filters": 32, "kernel_size": 3, "dropout": 0.5, "dropout_fc": 0.4, "learning_rate": 0.01, "dropout_rate": 0.5}}, "metrics": {"metrics": {}}, "score": null, "best_step": 0, "status": "FAILED", "message": "Traceback (most recent call last):\n  File \"c:\\Users\\0871\\.conda\\envs\\colab\\lib\\site-packages\\keras_tuner\\src\\engine\\base_tuner.py\", line 274, in _try_run_and_update_trial\n    self._run_and_update_trial(trial, *fit_args, **fit_kwargs)\n  File \"c:\\Users\\0871\\.conda\\envs\\colab\\lib\\site-packages\\keras_tuner\\src\\engine\\base_tuner.py\", line 239, in _run_and_update_trial\n    results = self.run_trial(trial, *fit_args, **fit_kwargs)\n  File \"c:\\Users\\0871\\.conda\\envs\\colab\\lib\\site-packages\\keras_tuner\\src\\engine\\tuner.py\", line 314, in run_trial\n    obj_value = self._build_and_fit_model(trial, *args, **copied_kwargs)\n  File \"c:\\Users\\0871\\.conda\\envs\\colab\\lib\\site-packages\\keras_tuner\\src\\engine\\tuner.py\", line 233, in _build_and_fit_model\n    results = self.hypermodel.fit(hp, model, *args, **kwargs)\n  File \"c:\\Users\\0871\\.conda\\envs\\colab\\lib\\site-packages\\keras_tuner\\src\\engine\\hypermodel.py\", line 149, in fit\n    return model.fit(*args, **kwargs)\n  File \"c:\\Users\\0871\\.conda\\envs\\colab\\lib\\site-packages\\keras\\src\\utils\\traceback_utils.py\", line 122, in error_handler\n    raise e.with_traceback(filtered_tb) from None\n  File \"c:\\Users\\0871\\.conda\\envs\\colab\\lib\\site-packages\\keras\\src\\utils\\traceback_utils.py\", line 122, in error_handler\n    raise e.with_traceback(filtered_tb) from None\nValueError: Exception encountered when calling Conv1D.call().\n\n\u001b[1mNegative dimension size caused by subtracting 3 from 2 for '{{node sequential_1/conv1d_1_2/convolution}} = Conv2D[T=DT_FLOAT, data_format=\"NHWC\", dilations=[1, 1, 1, 1], explicit_paddings=[], padding=\"VALID\", strides=[1, 1, 1, 1], use_cudnn_on_gpu=true](sequential_1/conv1d_1_2/convolution/ExpandDims, sequential_1/conv1d_1_2/convolution/ExpandDims_1)' with input shapes: [?,1,2,32], [1,3,32,32].\u001b[0m\n\nArguments received by Conv1D.call():\n  \u2022 inputs=tf.Tensor(shape=(None, 2, 32), dtype=float32)\n"}